[2023-04-27T07:06:15.160+0000] {taskinstance.py:1090} INFO - Dependencies all met for dep_context=non-requeueable deps ti=<TaskInstance: weather_dag_api.cities.insert_data_Odesa scheduled__2023-04-26T00:00:00+00:00 [queued]>
[2023-04-27T07:06:15.482+0000] {taskinstance.py:1090} INFO - Dependencies all met for dep_context=requeueable deps ti=<TaskInstance: weather_dag_api.cities.insert_data_Odesa scheduled__2023-04-26T00:00:00+00:00 [queued]>
[2023-04-27T07:06:15.488+0000] {taskinstance.py:1288} INFO - 
--------------------------------------------------------------------------------
[2023-04-27T07:06:15.501+0000] {taskinstance.py:1289} INFO - Starting attempt 1 of 1
[2023-04-27T07:06:15.511+0000] {taskinstance.py:1290} INFO - 
--------------------------------------------------------------------------------
[2023-04-27T07:06:16.607+0000] {taskinstance.py:1309} INFO - Executing <Task(PostgresOperator): cities.insert_data_Odesa> on 2023-04-26 00:00:00+00:00
[2023-04-27T07:06:16.733+0000] {standard_task_runner.py:55} INFO - Started process 739 to run task
[2023-04-27T07:06:16.807+0000] {standard_task_runner.py:82} INFO - Running: ['***', 'tasks', 'run', 'weather_dag_api', 'cities.insert_data_Odesa', 'scheduled__2023-04-26T00:00:00+00:00', '--job-id', '118', '--raw', '--subdir', 'DAGS_FOLDER/weather_dag_api.py', '--cfg-path', '/tmp/tmp5u4an5mz']
[2023-04-27T07:06:16.809+0000] {standard_task_runner.py:83} INFO - Job 118: Subtask cities.insert_data_Odesa
[2023-04-27T07:06:17.488+0000] {task_command.py:389} INFO - Running <TaskInstance: weather_dag_api.cities.insert_data_Odesa scheduled__2023-04-26T00:00:00+00:00 [running]> on host 80d943d8f5b4
[2023-04-27T07:06:20.595+0000] {taskinstance.py:1518} INFO - Exporting the following env vars:
AIRFLOW_CTX_DAG_OWNER=***
AIRFLOW_CTX_DAG_ID=weather_dag_api
AIRFLOW_CTX_TASK_ID=cities.insert_data_Odesa
AIRFLOW_CTX_EXECUTION_DATE=2023-04-26T00:00:00+00:00
AIRFLOW_CTX_TRY_NUMBER=1
AIRFLOW_CTX_DAG_RUN_ID=scheduled__2023-04-26T00:00:00+00:00
[2023-04-27T07:06:20.677+0000] {sql.py:254} INFO - Executing: INSERT INTO measurements (timestamp, temp, precipitation, wind_speed, location) 
				VALUES ('2023-04-26T05:20:00Z',
				12.7,
				0.0,
				6.4,
				'Odesa)';
[2023-04-27T07:06:20.759+0000] {base.py:73} INFO - Using connection ID 'postgres_conn' for task execution.
[2023-04-27T07:07:22.698+0000] {base.py:73} INFO - Using connection ID 'postgres_conn' for task execution.
[2023-04-27T07:07:22.740+0000] {sql.py:375} INFO - Running statement: INSERT INTO measurements (timestamp, temp, precipitation, wind_speed, location) 
				VALUES ('2023-04-26T05:20:00Z',
				12.7,
				0.0,
				6.4,
				'Odesa)';, parameters: None
[2023-04-27T07:07:22.764+0000] {taskinstance.py:1776} ERROR - Task failed with exception
Traceback (most recent call last):
  File "/home/airflow/.local/lib/python3.7/site-packages/airflow/providers/common/sql/operators/sql.py", line 266, in execute
    **extra_kwargs,
  File "/home/airflow/.local/lib/python3.7/site-packages/airflow/providers/common/sql/hooks/sql.py", line 349, in run
    self._run_command(cur, sql_statement, parameters)
  File "/home/airflow/.local/lib/python3.7/site-packages/airflow/providers/common/sql/hooks/sql.py", line 380, in _run_command
    cur.execute(sql_statement)
psycopg2.errors.SyntaxError: syntax error at or near ";"
LINE 6:     'Odesa)';
                    ^

[2023-04-27T07:07:23.318+0000] {taskinstance.py:1332} INFO - Marking task as FAILED. dag_id=weather_dag_api, task_id=cities.insert_data_Odesa, execution_date=20230426T000000, start_date=20230427T070615, end_date=20230427T070723
[2023-04-27T07:07:23.690+0000] {standard_task_runner.py:105} ERROR - Failed to execute job 118 for task cities.insert_data_Odesa (syntax error at or near ";"
LINE 6:     'Odesa)';
                    ^
; 739)
[2023-04-27T07:07:24.407+0000] {local_task_job.py:212} INFO - Task exited with return code 1
[2023-04-27T07:07:25.630+0000] {taskinstance.py:2596} INFO - 0 downstream tasks scheduled from follow-on schedule check
