[2023-04-26T16:50:19.341+0000] {taskinstance.py:1090} INFO - Dependencies all met for dep_context=non-requeueable deps ti=<TaskInstance: weather_dag_api.cities.insert_data_Kyiv manual__2023-04-26T16:49:45.722640+00:00 [queued]>
[2023-04-26T16:50:19.459+0000] {taskinstance.py:1090} INFO - Dependencies all met for dep_context=requeueable deps ti=<TaskInstance: weather_dag_api.cities.insert_data_Kyiv manual__2023-04-26T16:49:45.722640+00:00 [queued]>
[2023-04-26T16:50:19.462+0000] {taskinstance.py:1288} INFO - 
--------------------------------------------------------------------------------
[2023-04-26T16:50:19.464+0000] {taskinstance.py:1289} INFO - Starting attempt 1 of 1
[2023-04-26T16:50:19.466+0000] {taskinstance.py:1290} INFO - 
--------------------------------------------------------------------------------
[2023-04-26T16:50:19.644+0000] {taskinstance.py:1309} INFO - Executing <Task(PostgresOperator): cities.insert_data_Kyiv> on 2023-04-26 16:49:45.722640+00:00
[2023-04-26T16:50:19.659+0000] {standard_task_runner.py:55} INFO - Started process 4851 to run task
[2023-04-26T16:50:19.686+0000] {standard_task_runner.py:82} INFO - Running: ['***', 'tasks', 'run', 'weather_dag_api', 'cities.insert_data_Kyiv', 'manual__2023-04-26T16:49:45.722640+00:00', '--job-id', '450', '--raw', '--subdir', 'DAGS_FOLDER/weather_dag_api.py', '--cfg-path', '/tmp/tmpihvo1uxv']
[2023-04-26T16:50:19.691+0000] {standard_task_runner.py:83} INFO - Job 450: Subtask cities.insert_data_Kyiv
[2023-04-26T16:50:20.212+0000] {task_command.py:389} INFO - Running <TaskInstance: weather_dag_api.cities.insert_data_Kyiv manual__2023-04-26T16:49:45.722640+00:00 [running]> on host d48b88797b3b
[2023-04-26T16:50:20.754+0000] {abstractoperator.py:615} ERROR - Exception rendering Jinja template for task 'cities.insert_data_Kyiv', field 'sql'. Template: "INSERT INTO measurements (temp) VALUES ({{ti.xcom_pull(task_ids='cities.process_data_{location}')[1]}});"
Traceback (most recent call last):
  File "/home/airflow/.local/lib/python3.7/site-packages/airflow/models/abstractoperator.py", line 607, in _do_render_template_fields
    seen_oids,
  File "/home/airflow/.local/lib/python3.7/site-packages/airflow/models/abstractoperator.py", line 665, in render_template
    return render_template_to_string(template, context)
  File "/home/airflow/.local/lib/python3.7/site-packages/airflow/utils/helpers.py", line 288, in render_template_to_string
    return render_template(template, cast(MutableMapping[str, Any], context), native=False)
  File "/home/airflow/.local/lib/python3.7/site-packages/airflow/utils/helpers.py", line 283, in render_template
    return "".join(nodes)
  File "<template>", line 13, in root
  File "/home/airflow/.local/lib/python3.7/site-packages/jinja2/runtime.py", line 852, in _fail_with_undefined_error
    raise self._undefined_exception(self._undefined_message)
jinja2.exceptions.UndefinedError: None has no element 1
[2023-04-26T16:50:20.785+0000] {taskinstance.py:1776} ERROR - Task failed with exception
Traceback (most recent call last):
  File "/home/airflow/.local/lib/python3.7/site-packages/airflow/models/taskinstance.py", line 1383, in _run_raw_task
    self._execute_task_with_callbacks(context, test_mode)
  File "/home/airflow/.local/lib/python3.7/site-packages/airflow/models/taskinstance.py", line 1502, in _execute_task_with_callbacks
    task_orig = self.render_templates(context=context)
  File "/home/airflow/.local/lib/python3.7/site-packages/airflow/models/taskinstance.py", line 2123, in render_templates
    original_task.render_template_fields(context)
  File "/home/airflow/.local/lib/python3.7/site-packages/airflow/models/baseoperator.py", line 1179, in render_template_fields
    self._do_render_template_fields(self, self.template_fields, context, jinja_env, set())
  File "/home/airflow/.local/lib/python3.7/site-packages/airflow/utils/session.py", line 75, in wrapper
    return func(*args, session=session, **kwargs)
  File "/home/airflow/.local/lib/python3.7/site-packages/airflow/models/abstractoperator.py", line 607, in _do_render_template_fields
    seen_oids,
  File "/home/airflow/.local/lib/python3.7/site-packages/airflow/models/abstractoperator.py", line 665, in render_template
    return render_template_to_string(template, context)
  File "/home/airflow/.local/lib/python3.7/site-packages/airflow/utils/helpers.py", line 288, in render_template_to_string
    return render_template(template, cast(MutableMapping[str, Any], context), native=False)
  File "/home/airflow/.local/lib/python3.7/site-packages/airflow/utils/helpers.py", line 283, in render_template
    return "".join(nodes)
  File "<template>", line 13, in root
  File "/home/airflow/.local/lib/python3.7/site-packages/jinja2/runtime.py", line 852, in _fail_with_undefined_error
    raise self._undefined_exception(self._undefined_message)
jinja2.exceptions.UndefinedError: None has no element 1
[2023-04-26T16:50:20.826+0000] {taskinstance.py:1332} INFO - Marking task as FAILED. dag_id=weather_dag_api, task_id=cities.insert_data_Kyiv, execution_date=20230426T164945, start_date=20230426T165019, end_date=20230426T165020
[2023-04-26T16:50:20.868+0000] {standard_task_runner.py:105} ERROR - Failed to execute job 450 for task cities.insert_data_Kyiv (None has no element 1; 4851)
[2023-04-26T16:50:20.962+0000] {local_task_job.py:212} INFO - Task exited with return code 1
[2023-04-26T16:50:21.005+0000] {taskinstance.py:2596} INFO - 0 downstream tasks scheduled from follow-on schedule check
