[2023-04-26T16:46:59.772+0000] {taskinstance.py:1090} INFO - Dependencies all met for dep_context=non-requeueable deps ti=<TaskInstance: weather_dag_api.cities.insert_data_Kharkiv manual__2023-04-26T16:46:17.435621+00:00 [queued]>
[2023-04-26T16:46:59.879+0000] {taskinstance.py:1090} INFO - Dependencies all met for dep_context=requeueable deps ti=<TaskInstance: weather_dag_api.cities.insert_data_Kharkiv manual__2023-04-26T16:46:17.435621+00:00 [queued]>
[2023-04-26T16:46:59.882+0000] {taskinstance.py:1288} INFO - 
--------------------------------------------------------------------------------
[2023-04-26T16:46:59.893+0000] {taskinstance.py:1289} INFO - Starting attempt 1 of 1
[2023-04-26T16:46:59.896+0000] {taskinstance.py:1290} INFO - 
--------------------------------------------------------------------------------
[2023-04-26T16:47:00.028+0000] {taskinstance.py:1309} INFO - Executing <Task(PostgresOperator): cities.insert_data_Kharkiv> on 2023-04-26 16:46:17.435621+00:00
[2023-04-26T16:47:00.056+0000] {standard_task_runner.py:55} INFO - Started process 4721 to run task
[2023-04-26T16:47:00.072+0000] {standard_task_runner.py:82} INFO - Running: ['***', 'tasks', 'run', 'weather_dag_api', 'cities.insert_data_Kharkiv', 'manual__2023-04-26T16:46:17.435621+00:00', '--job-id', '416', '--raw', '--subdir', 'DAGS_FOLDER/weather_dag_final.py', '--cfg-path', '/tmp/tmpe9b6kqnk']
[2023-04-26T16:47:00.077+0000] {standard_task_runner.py:83} INFO - Job 416: Subtask cities.insert_data_Kharkiv
[2023-04-26T16:47:00.278+0000] {task_command.py:389} INFO - Running <TaskInstance: weather_dag_api.cities.insert_data_Kharkiv manual__2023-04-26T16:46:17.435621+00:00 [running]> on host d48b88797b3b
[2023-04-26T16:47:00.368+0000] {abstractoperator.py:615} ERROR - Exception rendering Jinja template for task 'cities.insert_data_Kharkiv', field 'sql'. Template: 'INSERT INTO measurements (timestamp, temp, precipitation, wind_speed, location) \n\t\t\t\tVALUES ({{ti.xcom_pull(task_ids=f"cities.process_data_Kharkiv")[0]}},\n\t\t\t\t{{ti.xcom_pull(task_ids=f"cities.process_data_Kharkiv")[1]}},\n\t\t\t\t{{ti.xcom_pull(task_ids=f"cities.process_data_Kharkiv")[2]}},\n\t\t\t\t{{ti.xcom_pull(task_ids=f"cities.process_data_Kharkiv")[3]}},\n\t\t\t\t{{ti.xcom_pull(task_ids=f"cities.process_data_Kharkiv")[4]}});'
Traceback (most recent call last):
  File "/home/airflow/.local/lib/python3.7/site-packages/airflow/models/abstractoperator.py", line 607, in _do_render_template_fields
    seen_oids,
  File "/home/airflow/.local/lib/python3.7/site-packages/airflow/models/abstractoperator.py", line 661, in render_template
    template = jinja_env.from_string(value)
  File "/home/airflow/.local/lib/python3.7/site-packages/jinja2/environment.py", line 1105, in from_string
    return cls.from_code(self, self.compile(source), gs, None)
  File "/home/airflow/.local/lib/python3.7/site-packages/jinja2/environment.py", line 768, in compile
    self.handle_exception(source=source_hint)
  File "/home/airflow/.local/lib/python3.7/site-packages/jinja2/environment.py", line 936, in handle_exception
    raise rewrite_traceback_stack(source=source)
  File "<unknown>", line 2, in template
jinja2.exceptions.TemplateSyntaxError: expected token ',', got 'string'
[2023-04-26T16:47:00.376+0000] {taskinstance.py:1776} ERROR - Task failed with exception
Traceback (most recent call last):
  File "/home/airflow/.local/lib/python3.7/site-packages/airflow/models/taskinstance.py", line 1383, in _run_raw_task
    self._execute_task_with_callbacks(context, test_mode)
  File "/home/airflow/.local/lib/python3.7/site-packages/airflow/models/taskinstance.py", line 1502, in _execute_task_with_callbacks
    task_orig = self.render_templates(context=context)
  File "/home/airflow/.local/lib/python3.7/site-packages/airflow/models/taskinstance.py", line 2123, in render_templates
    original_task.render_template_fields(context)
  File "/home/airflow/.local/lib/python3.7/site-packages/airflow/models/baseoperator.py", line 1179, in render_template_fields
    self._do_render_template_fields(self, self.template_fields, context, jinja_env, set())
  File "/home/airflow/.local/lib/python3.7/site-packages/airflow/utils/session.py", line 75, in wrapper
    return func(*args, session=session, **kwargs)
  File "/home/airflow/.local/lib/python3.7/site-packages/airflow/models/abstractoperator.py", line 607, in _do_render_template_fields
    seen_oids,
  File "/home/airflow/.local/lib/python3.7/site-packages/airflow/models/abstractoperator.py", line 661, in render_template
    template = jinja_env.from_string(value)
  File "/home/airflow/.local/lib/python3.7/site-packages/jinja2/environment.py", line 1105, in from_string
    return cls.from_code(self, self.compile(source), gs, None)
  File "/home/airflow/.local/lib/python3.7/site-packages/jinja2/environment.py", line 768, in compile
    self.handle_exception(source=source_hint)
  File "/home/airflow/.local/lib/python3.7/site-packages/jinja2/environment.py", line 936, in handle_exception
    raise rewrite_traceback_stack(source=source)
  File "<unknown>", line 2, in template
jinja2.exceptions.TemplateSyntaxError: expected token ',', got 'string'
[2023-04-26T16:47:00.489+0000] {taskinstance.py:1332} INFO - Marking task as FAILED. dag_id=weather_dag_api, task_id=cities.insert_data_Kharkiv, execution_date=20230426T164617, start_date=20230426T164659, end_date=20230426T164700
[2023-04-26T16:47:00.521+0000] {standard_task_runner.py:105} ERROR - Failed to execute job 416 for task cities.insert_data_Kharkiv (expected token ',', got 'string'; 4721)
[2023-04-26T16:47:00.570+0000] {local_task_job.py:212} INFO - Task exited with return code 1
[2023-04-26T16:47:00.686+0000] {taskinstance.py:2596} INFO - 0 downstream tasks scheduled from follow-on schedule check
