[2023-04-25T20:32:13.483+0000] {taskinstance.py:1090} INFO - Dependencies all met for dep_context=non-requeueable deps ti=<TaskInstance: weather_dag_api.process_data manual__2023-04-25T20:31:59.639044+00:00 [queued]>
[2023-04-25T20:32:13.522+0000] {taskinstance.py:1090} INFO - Dependencies all met for dep_context=requeueable deps ti=<TaskInstance: weather_dag_api.process_data manual__2023-04-25T20:31:59.639044+00:00 [queued]>
[2023-04-25T20:32:13.526+0000] {taskinstance.py:1288} INFO - 
--------------------------------------------------------------------------------
[2023-04-25T20:32:13.530+0000] {taskinstance.py:1289} INFO - Starting attempt 1 of 1
[2023-04-25T20:32:13.531+0000] {taskinstance.py:1290} INFO - 
--------------------------------------------------------------------------------
[2023-04-25T20:32:13.591+0000] {taskinstance.py:1309} INFO - Executing <Task(PythonOperator): process_data> on 2023-04-25 20:31:59.639044+00:00
[2023-04-25T20:32:13.611+0000] {standard_task_runner.py:55} INFO - Started process 2219 to run task
[2023-04-25T20:32:13.630+0000] {standard_task_runner.py:82} INFO - Running: ['***', 'tasks', 'run', 'weather_dag_api', 'process_data', 'manual__2023-04-25T20:31:59.639044+00:00', '--job-id', '32', '--raw', '--subdir', 'DAGS_FOLDER/weather_dag_api.py', '--cfg-path', '/tmp/tmp8tdw7y3l']
[2023-04-25T20:32:13.634+0000] {standard_task_runner.py:83} INFO - Job 32: Subtask process_data
[2023-04-25T20:32:13.838+0000] {task_command.py:389} INFO - Running <TaskInstance: weather_dag_api.process_data manual__2023-04-25T20:31:59.639044+00:00 [running]> on host 9dd0afd831d3
[2023-04-25T20:32:14.070+0000] {taskinstance.py:1518} INFO - Exporting the following env vars:
AIRFLOW_CTX_DAG_OWNER=***
AIRFLOW_CTX_DAG_ID=weather_dag_api
AIRFLOW_CTX_TASK_ID=process_data
AIRFLOW_CTX_EXECUTION_DATE=2023-04-25T20:31:59.639044+00:00
AIRFLOW_CTX_TRY_NUMBER=1
AIRFLOW_CTX_DAG_RUN_ID=manual__2023-04-25T20:31:59.639044+00:00
[2023-04-25T20:32:14.111+0000] {taskinstance.py:1776} ERROR - Task failed with exception
Traceback (most recent call last):
  File "/home/airflow/.local/lib/python3.7/site-packages/airflow/operators/python.py", line 175, in execute
    return_value = self.execute_callable()
  File "/home/airflow/.local/lib/python3.7/site-packages/airflow/operators/python.py", line 192, in execute_callable
    return self.python_callable(*self.op_args, **self.op_kwargs)
  File "/opt/airflow/dags/weather_dag_api.py", line 24, in process_weather_data
    print(info.data.parameter.coordinates.dates.value)
AttributeError: 'dict' object has no attribute 'data'
[2023-04-25T20:32:14.135+0000] {taskinstance.py:1332} INFO - Marking task as FAILED. dag_id=weather_dag_api, task_id=process_data, execution_date=20230425T203159, start_date=20230425T203213, end_date=20230425T203214
[2023-04-25T20:32:14.169+0000] {standard_task_runner.py:105} ERROR - Failed to execute job 32 for task process_data ('dict' object has no attribute 'data'; 2219)
[2023-04-25T20:32:14.215+0000] {local_task_job.py:212} INFO - Task exited with return code 1
[2023-04-25T20:32:14.268+0000] {taskinstance.py:2596} INFO - 0 downstream tasks scheduled from follow-on schedule check
