[2023-04-26T15:04:23.906+0000] {taskinstance.py:1090} INFO - Dependencies all met for dep_context=non-requeueable deps ti=<TaskInstance: weather_dag_api.cities.insert_data_Kharkiv manual__2023-04-26T15:03:47.648336+00:00 [queued]>
[2023-04-26T15:04:24.208+0000] {taskinstance.py:1090} INFO - Dependencies all met for dep_context=requeueable deps ti=<TaskInstance: weather_dag_api.cities.insert_data_Kharkiv manual__2023-04-26T15:03:47.648336+00:00 [queued]>
[2023-04-26T15:04:24.218+0000] {taskinstance.py:1288} INFO - 
--------------------------------------------------------------------------------
[2023-04-26T15:04:24.229+0000] {taskinstance.py:1289} INFO - Starting attempt 1 of 1
[2023-04-26T15:04:24.236+0000] {taskinstance.py:1290} INFO - 
--------------------------------------------------------------------------------
[2023-04-26T15:04:24.489+0000] {taskinstance.py:1309} INFO - Executing <Task(PostgresOperator): cities.insert_data_Kharkiv> on 2023-04-26 15:03:47.648336+00:00
[2023-04-26T15:04:24.555+0000] {standard_task_runner.py:55} INFO - Started process 2211 to run task
[2023-04-26T15:04:24.613+0000] {standard_task_runner.py:82} INFO - Running: ['***', 'tasks', 'run', 'weather_dag_api', 'cities.insert_data_Kharkiv', 'manual__2023-04-26T15:03:47.648336+00:00', '--job-id', '90', '--raw', '--subdir', 'DAGS_FOLDER/weather_dag_api.py', '--cfg-path', '/tmp/tmpavvj6t2b']
[2023-04-26T15:04:24.638+0000] {standard_task_runner.py:83} INFO - Job 90: Subtask cities.insert_data_Kharkiv
[2023-04-26T15:04:26.263+0000] {task_command.py:389} INFO - Running <TaskInstance: weather_dag_api.cities.insert_data_Kharkiv manual__2023-04-26T15:03:47.648336+00:00 [running]> on host d48b88797b3b
[2023-04-26T15:04:27.172+0000] {abstractoperator.py:615} ERROR - Exception rendering Jinja template for task 'cities.insert_data_Kharkiv', field 'sql'. Template: "INSERT INTO measurements (timestamp, temp, precipitation, wind_speed, location)\n\t\t\t\tVALUES ('{{ti.xcom_pull(task_ids='process_data')[0]}}',\n\t\t\t\t{{ti.xcom_pull(task_ids='process_data')[1]}},\n\t\t\t\t{{ti.xcom_pull(task_ids='process_data')[2]}},\n\t\t\t\t{{ti.xcom_pull(task_ids='process_data')[3]}},\n\t\t\t\t{{ti.xcom_pull(task_ids='process_data')[4]}});"
Traceback (most recent call last):
  File "/home/airflow/.local/lib/python3.7/site-packages/airflow/models/abstractoperator.py", line 607, in _do_render_template_fields
    seen_oids,
  File "/home/airflow/.local/lib/python3.7/site-packages/airflow/models/abstractoperator.py", line 665, in render_template
    return render_template_to_string(template, context)
  File "/home/airflow/.local/lib/python3.7/site-packages/airflow/utils/helpers.py", line 288, in render_template_to_string
    return render_template(template, cast(MutableMapping[str, Any], context), native=False)
  File "/home/airflow/.local/lib/python3.7/site-packages/airflow/utils/helpers.py", line 283, in render_template
    return "".join(nodes)
  File "<template>", line 13, in root
  File "/home/airflow/.local/lib/python3.7/site-packages/jinja2/runtime.py", line 852, in _fail_with_undefined_error
    raise self._undefined_exception(self._undefined_message)
jinja2.exceptions.UndefinedError: None has no element 0
[2023-04-26T15:04:27.176+0000] {taskinstance.py:1776} ERROR - Task failed with exception
Traceback (most recent call last):
  File "/home/airflow/.local/lib/python3.7/site-packages/airflow/models/taskinstance.py", line 1383, in _run_raw_task
    self._execute_task_with_callbacks(context, test_mode)
  File "/home/airflow/.local/lib/python3.7/site-packages/airflow/models/taskinstance.py", line 1502, in _execute_task_with_callbacks
    task_orig = self.render_templates(context=context)
  File "/home/airflow/.local/lib/python3.7/site-packages/airflow/models/taskinstance.py", line 2123, in render_templates
    original_task.render_template_fields(context)
  File "/home/airflow/.local/lib/python3.7/site-packages/airflow/models/baseoperator.py", line 1179, in render_template_fields
    self._do_render_template_fields(self, self.template_fields, context, jinja_env, set())
  File "/home/airflow/.local/lib/python3.7/site-packages/airflow/utils/session.py", line 75, in wrapper
    return func(*args, session=session, **kwargs)
  File "/home/airflow/.local/lib/python3.7/site-packages/airflow/models/abstractoperator.py", line 607, in _do_render_template_fields
    seen_oids,
  File "/home/airflow/.local/lib/python3.7/site-packages/airflow/models/abstractoperator.py", line 665, in render_template
    return render_template_to_string(template, context)
  File "/home/airflow/.local/lib/python3.7/site-packages/airflow/utils/helpers.py", line 288, in render_template_to_string
    return render_template(template, cast(MutableMapping[str, Any], context), native=False)
  File "/home/airflow/.local/lib/python3.7/site-packages/airflow/utils/helpers.py", line 283, in render_template
    return "".join(nodes)
  File "<template>", line 13, in root
  File "/home/airflow/.local/lib/python3.7/site-packages/jinja2/runtime.py", line 852, in _fail_with_undefined_error
    raise self._undefined_exception(self._undefined_message)
jinja2.exceptions.UndefinedError: None has no element 0
[2023-04-26T15:04:27.215+0000] {taskinstance.py:1332} INFO - Marking task as FAILED. dag_id=weather_dag_api, task_id=cities.insert_data_Kharkiv, execution_date=20230426T150347, start_date=20230426T150423, end_date=20230426T150427
[2023-04-26T15:04:27.348+0000] {standard_task_runner.py:105} ERROR - Failed to execute job 90 for task cities.insert_data_Kharkiv (None has no element 0; 2211)
[2023-04-26T15:04:27.411+0000] {local_task_job.py:212} INFO - Task exited with return code 1
[2023-04-26T15:04:27.563+0000] {taskinstance.py:2596} INFO - 0 downstream tasks scheduled from follow-on schedule check
