[2023-04-26T16:04:56.809+0000] {taskinstance.py:1090} INFO - Dependencies all met for dep_context=non-requeueable deps ti=<TaskInstance: weather_dag_api.cities.insert_data_Kyiv manual__2023-04-26T16:04:23.143867+00:00 [queued]>
[2023-04-26T16:04:56.879+0000] {taskinstance.py:1090} INFO - Dependencies all met for dep_context=requeueable deps ti=<TaskInstance: weather_dag_api.cities.insert_data_Kyiv manual__2023-04-26T16:04:23.143867+00:00 [queued]>
[2023-04-26T16:04:56.881+0000] {taskinstance.py:1288} INFO - 
--------------------------------------------------------------------------------
[2023-04-26T16:04:56.893+0000] {taskinstance.py:1289} INFO - Starting attempt 1 of 1
[2023-04-26T16:04:56.894+0000] {taskinstance.py:1290} INFO - 
--------------------------------------------------------------------------------
[2023-04-26T16:04:57.025+0000] {taskinstance.py:1309} INFO - Executing <Task(PostgresOperator): cities.insert_data_Kyiv> on 2023-04-26 16:04:23.143867+00:00
[2023-04-26T16:04:57.090+0000] {standard_task_runner.py:55} INFO - Started process 3716 to run task
[2023-04-26T16:04:57.087+0000] {standard_task_runner.py:82} INFO - Running: ['***', 'tasks', 'run', 'weather_dag_api', 'cities.insert_data_Kyiv', 'manual__2023-04-26T16:04:23.143867+00:00', '--job-id', '293', '--raw', '--subdir', 'DAGS_FOLDER/weather_dag_final.py', '--cfg-path', '/tmp/tmpynm8twey']
[2023-04-26T16:04:57.103+0000] {standard_task_runner.py:83} INFO - Job 293: Subtask cities.insert_data_Kyiv
[2023-04-26T16:04:57.669+0000] {task_command.py:389} INFO - Running <TaskInstance: weather_dag_api.cities.insert_data_Kyiv manual__2023-04-26T16:04:23.143867+00:00 [running]> on host d48b88797b3b
[2023-04-26T16:04:57.940+0000] {abstractoperator.py:615} ERROR - Exception rendering Jinja template for task 'cities.insert_data_Kyiv', field 'sql'. Template: 'INSERT INTO measurements (timestamp, temp, precipitation, wind_speed, location) \n\t\t\t\tVALUES ({{ti.xcom_pull(task_ids=f"cities.process_data_Kyiv")[0]}},\n\t\t\t\t{{ti.xcom_pull(task_ids=f"cities.process_data_Kyiv")[1]}},\n\t\t\t\t{{ti.xcom_pull(task_ids=f"cities.process_data_Kyiv")[2]}},\n\t\t\t\t{{ti.xcom_pull(task_ids=f"cities.process_data_Kyiv")[3]}},\n\t\t\t\t{{ti.xcom_pull(task_ids=f"cities.process_data_Kyiv")[4]}});'
Traceback (most recent call last):
  File "/home/airflow/.local/lib/python3.7/site-packages/airflow/models/abstractoperator.py", line 607, in _do_render_template_fields
    seen_oids,
  File "/home/airflow/.local/lib/python3.7/site-packages/airflow/models/abstractoperator.py", line 661, in render_template
    template = jinja_env.from_string(value)
  File "/home/airflow/.local/lib/python3.7/site-packages/jinja2/environment.py", line 1105, in from_string
    return cls.from_code(self, self.compile(source), gs, None)
  File "/home/airflow/.local/lib/python3.7/site-packages/jinja2/environment.py", line 768, in compile
    self.handle_exception(source=source_hint)
  File "/home/airflow/.local/lib/python3.7/site-packages/jinja2/environment.py", line 936, in handle_exception
    raise rewrite_traceback_stack(source=source)
  File "<unknown>", line 2, in template
jinja2.exceptions.TemplateSyntaxError: expected token ',', got 'string'
[2023-04-26T16:04:57.966+0000] {taskinstance.py:1776} ERROR - Task failed with exception
Traceback (most recent call last):
  File "/home/airflow/.local/lib/python3.7/site-packages/airflow/models/taskinstance.py", line 1383, in _run_raw_task
    self._execute_task_with_callbacks(context, test_mode)
  File "/home/airflow/.local/lib/python3.7/site-packages/airflow/models/taskinstance.py", line 1502, in _execute_task_with_callbacks
    task_orig = self.render_templates(context=context)
  File "/home/airflow/.local/lib/python3.7/site-packages/airflow/models/taskinstance.py", line 2123, in render_templates
    original_task.render_template_fields(context)
  File "/home/airflow/.local/lib/python3.7/site-packages/airflow/models/baseoperator.py", line 1179, in render_template_fields
    self._do_render_template_fields(self, self.template_fields, context, jinja_env, set())
  File "/home/airflow/.local/lib/python3.7/site-packages/airflow/utils/session.py", line 75, in wrapper
    return func(*args, session=session, **kwargs)
  File "/home/airflow/.local/lib/python3.7/site-packages/airflow/models/abstractoperator.py", line 607, in _do_render_template_fields
    seen_oids,
  File "/home/airflow/.local/lib/python3.7/site-packages/airflow/models/abstractoperator.py", line 661, in render_template
    template = jinja_env.from_string(value)
  File "/home/airflow/.local/lib/python3.7/site-packages/jinja2/environment.py", line 1105, in from_string
    return cls.from_code(self, self.compile(source), gs, None)
  File "/home/airflow/.local/lib/python3.7/site-packages/jinja2/environment.py", line 768, in compile
    self.handle_exception(source=source_hint)
  File "/home/airflow/.local/lib/python3.7/site-packages/jinja2/environment.py", line 936, in handle_exception
    raise rewrite_traceback_stack(source=source)
  File "<unknown>", line 2, in template
jinja2.exceptions.TemplateSyntaxError: expected token ',', got 'string'
[2023-04-26T16:04:57.995+0000] {taskinstance.py:1332} INFO - Marking task as FAILED. dag_id=weather_dag_api, task_id=cities.insert_data_Kyiv, execution_date=20230426T160423, start_date=20230426T160456, end_date=20230426T160457
[2023-04-26T16:04:58.054+0000] {standard_task_runner.py:105} ERROR - Failed to execute job 293 for task cities.insert_data_Kyiv (expected token ',', got 'string'; 3716)
[2023-04-26T16:04:58.110+0000] {local_task_job.py:212} INFO - Task exited with return code 1
[2023-04-26T16:04:58.438+0000] {taskinstance.py:2596} INFO - 0 downstream tasks scheduled from follow-on schedule check
