[2023-04-26T18:53:24.438+0000] {taskinstance.py:1090} INFO - Dependencies all met for dep_context=non-requeueable deps ti=<TaskInstance: weather_dag_api.cities.insert_data_Zhmerynka manual__2023-04-26T18:52:36.695783+00:00 [queued]>
[2023-04-26T18:53:24.635+0000] {taskinstance.py:1090} INFO - Dependencies all met for dep_context=requeueable deps ti=<TaskInstance: weather_dag_api.cities.insert_data_Zhmerynka manual__2023-04-26T18:52:36.695783+00:00 [queued]>
[2023-04-26T18:53:24.646+0000] {taskinstance.py:1288} INFO - 
--------------------------------------------------------------------------------
[2023-04-26T18:53:24.706+0000] {taskinstance.py:1289} INFO - Starting attempt 1 of 1
[2023-04-26T18:53:24.708+0000] {taskinstance.py:1290} INFO - 
--------------------------------------------------------------------------------
[2023-04-26T18:53:24.930+0000] {taskinstance.py:1309} INFO - Executing <Task(PostgresOperator): cities.insert_data_Zhmerynka> on 2023-04-26 18:52:36.695783+00:00
[2023-04-26T18:53:24.987+0000] {standard_task_runner.py:55} INFO - Started process 2348 to run task
[2023-04-26T18:53:25.121+0000] {standard_task_runner.py:82} INFO - Running: ['***', 'tasks', 'run', 'weather_dag_api', 'cities.insert_data_Zhmerynka', 'manual__2023-04-26T18:52:36.695783+00:00', '--job-id', '455', '--raw', '--subdir', 'DAGS_FOLDER/weather_dag_api.py', '--cfg-path', '/tmp/tmpzaqg_yat']
[2023-04-26T18:53:25.150+0000] {standard_task_runner.py:83} INFO - Job 455: Subtask cities.insert_data_Zhmerynka
[2023-04-26T18:53:25.644+0000] {task_command.py:389} INFO - Running <TaskInstance: weather_dag_api.cities.insert_data_Zhmerynka manual__2023-04-26T18:52:36.695783+00:00 [running]> on host b46a99c748bd
[2023-04-26T18:53:26.461+0000] {taskinstance.py:1518} INFO - Exporting the following env vars:
AIRFLOW_CTX_DAG_OWNER=***
AIRFLOW_CTX_DAG_ID=weather_dag_api
AIRFLOW_CTX_TASK_ID=cities.insert_data_Zhmerynka
AIRFLOW_CTX_EXECUTION_DATE=2023-04-26T18:52:36.695783+00:00
AIRFLOW_CTX_TRY_NUMBER=1
AIRFLOW_CTX_DAG_RUN_ID=manual__2023-04-26T18:52:36.695783+00:00
[2023-04-26T18:53:26.463+0000] {sql.py:254} INFO - Executing: INSERT INTO measurements (temp) VALUES ("None")
[2023-04-26T18:53:26.517+0000] {base.py:73} INFO - Using connection ID 'postgres_conn' for task execution.
[2023-04-26T18:53:31.324+0000] {base.py:73} INFO - Using connection ID 'postgres_conn' for task execution.
[2023-04-26T18:53:31.390+0000] {sql.py:375} INFO - Running statement: INSERT INTO measurements (temp) VALUES ("None"), parameters: None
[2023-04-26T18:53:31.426+0000] {taskinstance.py:1776} ERROR - Task failed with exception
Traceback (most recent call last):
  File "/home/airflow/.local/lib/python3.7/site-packages/airflow/providers/common/sql/operators/sql.py", line 266, in execute
    **extra_kwargs,
  File "/home/airflow/.local/lib/python3.7/site-packages/airflow/providers/common/sql/hooks/sql.py", line 349, in run
    self._run_command(cur, sql_statement, parameters)
  File "/home/airflow/.local/lib/python3.7/site-packages/airflow/providers/common/sql/hooks/sql.py", line 380, in _run_command
    cur.execute(sql_statement)
psycopg2.errors.UndefinedColumn: column "None" does not exist
LINE 1: INSERT INTO measurements (temp) VALUES ("None")
                                                ^

[2023-04-26T18:53:31.734+0000] {taskinstance.py:1332} INFO - Marking task as FAILED. dag_id=weather_dag_api, task_id=cities.insert_data_Zhmerynka, execution_date=20230426T185236, start_date=20230426T185324, end_date=20230426T185331
[2023-04-26T18:53:32.454+0000] {standard_task_runner.py:105} ERROR - Failed to execute job 455 for task cities.insert_data_Zhmerynka (column "None" does not exist
LINE 1: INSERT INTO measurements (temp) VALUES ("None")
                                                ^
; 2348)
[2023-04-26T18:53:32.732+0000] {local_task_job.py:212} INFO - Task exited with return code 1
[2023-04-26T18:53:32.958+0000] {taskinstance.py:2596} INFO - 0 downstream tasks scheduled from follow-on schedule check
